{"name": "test_add_02", "status": "broken", "statusDetails": {"message": "TypeError: test_add_02() takes 0 positional arguments but 1 was given", "trace": "cls = <class '_pytest.runner.CallInfo'>\nfunc = <function call_runtest_hook.<locals>.<lambda> at 0x0000029C5D6955E0>, when = 'call'\nreraise = (<class '_pytest.outcomes.Exit'>, <class 'KeyboardInterrupt'>)\n\n    @classmethod\n    def from_call(\n        cls,\n        func: \"Callable[[], TResult]\",\n        when: \"Literal['collect', 'setup', 'call', 'teardown']\",\n        reraise: Optional[\n            Union[Type[BaseException], Tuple[Type[BaseException], ...]]\n        ] = None,\n    ) -> \"CallInfo[TResult]\":\n        excinfo = None\n        start = timing.time()\n        precise_start = timing.perf_counter()\n        try:\n>           result: Optional[TResult] = func()\n\n..\\..\\appdata\\local\\programs\\python\\python39\\lib\\site-packages\\_pytest\\runner.py:311: \n_ _ _ _ _ _ _ _ _ _ _ _ _ _ _ _ _ _ _ _ _ _ _ _ _ _ _ _ _ _ _ _ _ _ _ _ _ _ _ _ _ _ _ _ _ _ _ _ _ _ _ _ _ _ \n..\\..\\appdata\\local\\programs\\python\\python39\\lib\\site-packages\\_pytest\\runner.py:255: in <lambda>\n    lambda: ihook(item=item, **kwds), when=when, reraise=reraise\n..\\..\\appdata\\local\\programs\\python\\python39\\lib\\site-packages\\pluggy\\hooks.py:286: in __call__\n    return self._hookexec(self, self.get_hookimpls(), kwargs)\n..\\..\\appdata\\local\\programs\\python\\python39\\lib\\site-packages\\pluggy\\manager.py:93: in _hookexec\n    return self._inner_hookexec(hook, methods, kwargs)\n..\\..\\appdata\\local\\programs\\python\\python39\\lib\\site-packages\\pluggy\\manager.py:84: in <lambda>\n    self._inner_hookexec = lambda hook, methods, kwargs: hook.multicall(\n..\\..\\appdata\\local\\programs\\python\\python39\\lib\\site-packages\\_pytest\\runner.py:170: in pytest_runtest_call\n    raise e\n..\\..\\appdata\\local\\programs\\python\\python39\\lib\\site-packages\\_pytest\\runner.py:162: in pytest_runtest_call\n    item.runtest()\n..\\..\\appdata\\local\\programs\\python\\python39\\lib\\site-packages\\_pytest\\python.py:1641: in runtest\n    self.ihook.pytest_pyfunc_call(pyfuncitem=self)\n..\\..\\appdata\\local\\programs\\python\\python39\\lib\\site-packages\\pluggy\\hooks.py:286: in __call__\n    return self._hookexec(self, self.get_hookimpls(), kwargs)\n..\\..\\appdata\\local\\programs\\python\\python39\\lib\\site-packages\\pluggy\\manager.py:93: in _hookexec\n    return self._inner_hookexec(hook, methods, kwargs)\n..\\..\\appdata\\local\\programs\\python\\python39\\lib\\site-packages\\pluggy\\manager.py:84: in <lambda>\n    self._inner_hookexec = lambda hook, methods, kwargs: hook.multicall(\n_ _ _ _ _ _ _ _ _ _ _ _ _ _ _ _ _ _ _ _ _ _ _ _ _ _ _ _ _ _ _ _ _ _ _ _ _ _ _ _ _ _ _ _ _ _ _ _ _ _ _ _ _ _ \n\npyfuncitem = <Function test_add_02>\n\n    @hookimpl(trylast=True)\n    def pytest_pyfunc_call(pyfuncitem: \"Function\") -> Optional[object]:\n        testfunction = pyfuncitem.obj\n        if is_async_function(testfunction):\n            async_warn_and_skip(pyfuncitem.nodeid)\n        funcargs = pyfuncitem.funcargs\n        testargs = {arg: funcargs[arg] for arg in pyfuncitem._fixtureinfo.argnames}\n>       result = testfunction(**testargs)\nE       TypeError: test_add_02() takes 0 positional arguments but 1 was given\n\n..\\..\\appdata\\local\\programs\\python\\python39\\lib\\site-packages\\_pytest\\python.py:183: TypeError"}, "start": 1618916107828, "stop": 1618916107828, "uuid": "0718b227-8e9f-4dad-8b4c-454f5028ff49", "historyId": "c54f3544787f79568af7566f3c6eac28", "testCaseId": "3d82d50f221aaefc32e60bb0ffb35270", "fullName": "test_mark.Test_Demo2#test_add_02", "labels": [{"name": "tag", "value": "demo"}, {"name": "tag", "value": "smoke"}, {"name": "suite", "value": "test_mark"}, {"name": "subSuite", "value": "Test_Demo2"}, {"name": "host", "value": "Tan"}, {"name": "thread", "value": "1092-MainThread"}, {"name": "framework", "value": "pytest"}, {"name": "language", "value": "cpython3"}, {"name": "package", "value": "test_mark"}]}